Traceback (most recent call last):
  File "/nobackup/users/sammit/anaconda3/envs/pyg-m1/bin/jupyter-nbconvert", line 6, in <module>
    from nbconvert.nbconvertapp import main
  File "/nobackup/users/sammit/anaconda3/envs/pyg-m1/lib/python3.10/site-packages/nbconvert/__init__.py", line 6, in <module>
    from . import filters, postprocessors, preprocessors, writers
  File "/nobackup/users/sammit/anaconda3/envs/pyg-m1/lib/python3.10/site-packages/nbconvert/filters/__init__.py", line 8, in <module>
    from .markdown import (
  File "/nobackup/users/sammit/anaconda3/envs/pyg-m1/lib/python3.10/site-packages/nbconvert/filters/markdown.py", line 13, in <module>
    from .markdown_mistune import markdown2html_mistune
  File "/nobackup/users/sammit/anaconda3/envs/pyg-m1/lib/python3.10/site-packages/nbconvert/filters/markdown_mistune.py", line 22, in <module>
    from nbconvert.filters.strings import add_anchor
  File "/nobackup/users/sammit/anaconda3/envs/pyg-m1/lib/python3.10/site-packages/nbconvert/filters/strings.py", line 23, in <module>
    from nbconvert.preprocessors.sanitize import _get_default_css_sanitizer
  File "/nobackup/users/sammit/anaconda3/envs/pyg-m1/lib/python3.10/site-packages/nbconvert/preprocessors/__init__.py", line 3, in <module>
    from nbclient.exceptions import CellExecutionError
  File "/nobackup/users/sammit/anaconda3/envs/pyg-m1/lib/python3.10/site-packages/nbclient/__init__.py", line 5, in <module>
    from .client import NotebookClient, execute  # noqa: F401
  File "/nobackup/users/sammit/anaconda3/envs/pyg-m1/lib/python3.10/site-packages/nbclient/client.py", line 17, in <module>
    from nbformat import NotebookNode
  File "/nobackup/users/sammit/anaconda3/envs/pyg-m1/lib/python3.10/site-packages/nbformat/__init__.py", line 11, in <module>
    from . import v1, v2, v3, v4
  File "/nobackup/users/sammit/anaconda3/envs/pyg-m1/lib/python3.10/site-packages/nbformat/v4/__init__.py", line 23, in <module>
    from .convert import downgrade, upgrade
  File "/nobackup/users/sammit/anaconda3/envs/pyg-m1/lib/python3.10/site-packages/nbformat/v4/convert.py", line 11, in <module>
    from nbformat import v3, validator
  File "/nobackup/users/sammit/anaconda3/envs/pyg-m1/lib/python3.10/site-packages/nbformat/validator.py", line 16, in <module>
    from .json_compat import ValidationError, _validator_for_name, get_current_validator
  File "/nobackup/users/sammit/anaconda3/envs/pyg-m1/lib/python3.10/site-packages/nbformat/json_compat.py", line 11, in <module>
    import jsonschema
  File "/nobackup/users/sammit/anaconda3/envs/pyg-m1/lib/python3.10/site-packages/jsonschema/__init__.py", line 13, in <module>
    from jsonschema._format import FormatChecker
  File "/nobackup/users/sammit/anaconda3/envs/pyg-m1/lib/python3.10/site-packages/jsonschema/_format.py", line 11, in <module>
    from jsonschema.exceptions import FormatError
  File "/nobackup/users/sammit/anaconda3/envs/pyg-m1/lib/python3.10/site-packages/jsonschema/exceptions.py", line 14, in <module>
    from attrs import define
  File "/nobackup/users/sammit/anaconda3/envs/pyg-m1/lib/python3.10/site-packages/attrs/__init__.py", line 3, in <module>
    from attr import (
  File "/nobackup/users/sammit/anaconda3/envs/pyg-m1/lib/python3.10/site-packages/attr/__init__.py", line 10, in <module>
    from . import converters, exceptions, filters, setters, validators
  File "<frozen importlib._bootstrap>", line 1027, in _find_and_load
  File "<frozen importlib._bootstrap>", line 1006, in _find_and_load_unlocked
  File "<frozen importlib._bootstrap>", line 688, in _load_unlocked
  File "<frozen importlib._bootstrap_external>", line 879, in exec_module
  File "<frozen importlib._bootstrap_external>", line 984, in get_code
  File "<frozen importlib._bootstrap_external>", line 610, in _classify_pyc
  File "<frozen importlib._bootstrap_external>", line 87, in _unpack_uint32
KeyboardInterrupt
